<?xml version="1.0" encoding="utf-8"?>
<robot
  name="r20_description"
  xmlns:xacro="http://ros.org/wiki/xacro">
<xacro:macro name="box_inertia" params="m w h d">
    <inertial>
      <origin xyz="0 0 0" rpy="${pi/2} 0 ${pi/2}"/>      
      <mass value="${m}"/>
      <inertia ixx="${(m/12) * (h*h + d*d)}" ixy="0.0" ixz="0.0" iyy="${(m/12) * (w*w + d*d)}" iyz="0.0" izz="${(m/12) * (w*w + h*h)}"/>
    </inertial>
  </xacro:macro>
  <link
    name="base_link">
    <inertial>
      <origin
        xyz="0.0035491 0.32033 -0.16842"
        rpy="0 0 0" />
      <mass
        value="12.438" />
      <inertia
        ixx="2.3693"
        ixy="0.088648"
        ixz="-0.03872"
        iyy="3.2867"
        iyz="-0.031602"
        izz="2.1637" />
    </inertial>
    <visual>
      <origin
        xyz="0 0 0"
        rpy="0 0 0" />
      <geometry>
        <mesh
          filename="package://r20_description/meshes/base_link.STL" />
      </geometry>
      <material
        name="">
        <color
          rgba="0.79216 0.81961 0.93333 1" />
      </material>
    </visual>
    <collision>
      <origin
        xyz="0 0 0"
        rpy="0 0 0" />
      <geometry>
        <mesh
          filename="package://r20_description/meshes/base_link.STL" />
      </geometry>
    </collision>
  </link>
  <link
    name="wheel_front_right_link">
    <inertial>
      <origin
        xyz="0.396208700870725 0.144571844547815 0.35792710266045"
        rpy="0 0 0" />
      <mass
        value="12.438331682443" />
      <inertia
        ixx="2.16450503067602"
        ixy="0.0315308651206383"
        ixz="0.04212193998267"
        iyy="3.27832296207346"
        iyz="0.124187299153229"
        izz="2.37691630945375" />
    </inertial>
    <visual>
      <origin
        xyz="0 0 0"
        rpy="0 0 0" />
      <geometry>
        <mesh
          filename="package://r20_description/meshes/wheel_front_right_link.STL" />
      </geometry>
      <material
        name="">
        <color
          rgba="0.792156862745098 0.819607843137255 0.933333333333333 1" />
      </material>
    </visual>
    <collision>
      <origin
        xyz="0 0 0"
        rpy="0 0 0" />
      <geometry>
        <mesh
          filename="package://r20_description/meshes/wheel_front_right_link.STL" />
      </geometry>
    </collision>
  </link>
  <joint
    name="wheel_front_right_joint"
    type="continuous">
    <origin
      xyz="-0.35239 -0.22411 0.16152"
      rpy="1.5314 -0.00059618 1.5607" />
    <parent
      link="base_link" />
    <child
      link="wheel_front_right_link" />
    <axis
      xyz="0.015366 -0.020671 0.99967" />
  </joint>
  <link
    name="wheel_front_left_link">
    <inertial>
      <origin
        xyz="-0.283108473798885 0.295175307719044 0.40213785508857"
        rpy="0 0 0" />
      <mass
        value="12.438331682443" />
      <inertia
        ixx="2.34184597765328"
        ixy="0.410353827356801"
        ixz="0.00396982650561848"
        iyy="3.11141483980135"
        iyz="-0.0905413509477505"
        izz="2.36648348474859" />
    </inertial>
    <visual>
      <origin
        xyz="0 0 0"
        rpy="0 0 0" />
      <geometry>
        <mesh
          filename="package://r20_description/meshes/wheel_front_left_link.STL" />
      </geometry>
      <material
        name="">
        <color
          rgba="0.792156862745098 0.819607843137255 0.933333333333333 1" />
      </material>
    </visual>
    <collision>
      <origin
        xyz="0 0 0"
        rpy="0 0 0" />
      <geometry>
        <mesh
          filename="package://r20_description/meshes/wheel_front_left_link.STL" />
      </geometry>
    </collision>
  </link>
  <joint
    name="wheel_front_left_joint"
    type="continuous">
    <origin
      xyz="0.39763 -0.22026 0.16991"
      rpy="1.5614 -0.43857 -1.5845" />
    <parent
      link="base_link" />
    <child
      link="wheel_front_left_link" />
    <axis
      xyz="0.015366 -0.020671 -0.99967" />
  </joint>
  <link
    name="wheel_rear_left_link">
    <inertial>
      <origin
        xyz="0.496660443639475 0.156408718729597 0.37363042371979"
        rpy="0 0 0" />
      <mass
        value="12.438331682443" />
      <inertia
        ixx="2.16451065423992"
        ixy="-0.0333575258367668"
        ixz="0.0399219038571316"
        iyy="3.29135856048791"
        iyz="-0.0597099223677499"
        izz="2.36387508747538" />
    </inertial>
    <visual>
      <origin
        xyz="0 0 0"
        rpy="0 0 0" />
      <geometry>
        <mesh
          filename="package://r20_description/meshes/wheel_rear_left_link.STL" />
      </geometry>
      <material
        name="">
        <color
          rgba="0.792156862745098 0.819607843137255 0.933333333333333 1" />
      </material>
    </visual>
    <collision>
      <origin
        xyz="0 0 0"
        rpy="0 0 0" />
      <geometry>
        <mesh
          filename="package://r20_description/meshes/wheel_rear_left_link.STL" />
      </geometry>
    </collision>
  </link>
  <!-- IMU Link -->
<link name="imu_link">
  <visual>
    <geometry>
      <box size="0.1 0.1 0.1"/>
    </geometry>
  </visual>

  <collision>
    <geometry>
      <box size="0.1 0.1 0.1"/>
    </geometry>
  </collision>
  <xacro:box_inertia m="0.1" w="0.1" d="0.1" h="0.1"/>
</link>
<!-- End IMU Link -->
<joint name="imu_joint" type="fixed">
    <parent link="base_link"/>
  <child link="imu_link"/>
  <origin xyz="0 0 1.01"/>
</joint>
<!-- Gazebo IMU -->
 <gazebo reference="imu_link">
  <sensor name="imu_sensor" type="imu">
   <plugin filename="libgazebo_ros_imu_sensor.so" name="imu_plugin">
      <ros>
        <namespace>/demo</namespace>
        <remapping>~/out:=imu</remapping>
      </ros>
      <initial_orientation_as_reference>false</initial_orientation_as_reference>
    </plugin>
    <always_on>true</always_on>
    <update_rate>100</update_rate>
    <visualize>true</visualize>
    <imu>
      <angular_velocity>
        <x>
          <noise type="gaussian">
            <mean>0.0</mean>
            <stddev>2e-4</stddev>
            <bias_mean>0.0000075</bias_mean>
            <bias_stddev>0.0000008</bias_stddev>
          </noise>
        </x>
        <y>
          <noise type="gaussian">
            <mean>0.0</mean>
            <stddev>2e-4</stddev>
            <bias_mean>0.0000075</bias_mean>
            <bias_stddev>0.0000008</bias_stddev>
          </noise>
        </y>
        <z>
          <noise type="gaussian">
            <mean>0.0</mean>
            <stddev>2e-4</stddev>
            <bias_mean>0.0000075</bias_mean>
            <bias_stddev>0.0000008</bias_stddev>
          </noise>
        </z>
      </angular_velocity>
      <linear_acceleration>
        <x>
          <noise type="gaussian">
            <mean>0.0</mean>
            <stddev>1.7e-2</stddev>
            <bias_mean>0.1</bias_mean>
            <bias_stddev>0.001</bias_stddev>
          </noise>
        </x>
        <y>
          <noise type="gaussian">
            <mean>0.0</mean>
            <stddev>1.7e-2</stddev>
            <bias_mean>0.1</bias_mean>
            <bias_stddev>0.001</bias_stddev>
          </noise>
        </y>
        <z>
          <noise type="gaussian">
            <mean>0.0</mean>
            <stddev>1.7e-2</stddev>
            <bias_mean>0.1</bias_mean>
            <bias_stddev>0.001</bias_stddev>
          </noise>
        </z>
      </linear_acceleration>
    </imu>
  </sensor>
</gazebo>
<gazebo>
  <plugin name='diff_drive' filename='libgazebo_ros_diff_drive.so'>
    <ros>
      <namespace>/demo</namespace>
    </ros>

    <!-- wheels -->
    <left_joint>wheel_rear_left_joint</left_joint>
    <right_joint>wheel_rear_right_joint</right_joint>

    <!-- kinematics -->
    <wheel_separation>2.4</wheel_separation>
    <wheel_diameter>0.2</wheel_diameter>

    <!-- limits -->
    <max_wheel_torque>20</max_wheel_torque>
    <max_wheel_acceleration>1.0</max_wheel_acceleration>

    <!-- output -->
    <publish_odom>true</publish_odom>
    <publish_odom_tf>false</publish_odom_tf>
    <publish_wheel_tf>true</publish_wheel_tf>

    <odometry_frame>odom</odometry_frame>
    <robot_base_frame>base_link</robot_base_frame>
  </plugin>
</gazebo>
<!-- End Gazebo -->
  <joint
    name="wheel_rear_left_joint"
    type="continuous">
    <origin
      xyz="0.37759 0.66092 0.15221"
      rpy="1.5398 -0.00041912 -1.5818" />
    <parent
      link="base_link" />
    <child
      link="wheel_rear_left_link" />
    <axis
      xyz="0.015366 -0.020671 -0.99967" />
  </joint>
  <link
    name="wheel_rear_right_link">
    <inertial>
      <origin
        xyz="0.238973617976979 0.457345236461402 0.356572040989878"
        rpy="0 0 0" />
      <mass
        value="12.438331682443" />
      <inertia
        ixx="3.25085474831488"
        ixy="-0.197665970086269"
        ixz="0.0854684526697235"
        iyy="2.19967449057884"
        iyz="-0.0549482989464778"
        izz="2.3692150633095" />
    </inertial>
    <visual>
      <origin
        xyz="0 0 0"
        rpy="0 0 0" />
      <geometry>
        <mesh
          filename="package://r20_description/meshes/wheel_rear_right_link.STL" />
      </geometry>
      <material
        name="">
        <color
          rgba="0.792156862745098 0.819607843137255 0.933333333333333 1" />
      </material>
    </visual>
    <collision>
      <origin
        xyz="0 0 0"
        rpy="0 0 0" />
      <geometry>
        <mesh
          filename="package://r20_description/meshes/wheel_rear_right_link.STL" />
      </geometry>
    </collision>
  </link>
  <joint
    name="wheel_rear_right_joint"
    type="continuous">
    <origin
      xyz="-0.34598 0.66096 0.15106"
      rpy="-1.5381 -1.4198 -1.6158" />
    <parent
      link="base_link" />
    <child
      link="wheel_rear_right_link" />
    <axis
      xyz="0.015366 -0.020671 0.99967" />
  </joint>
</robot>
